Workbook
Name CityRegion: lookups!$A$1:$B$11
Name NativeTimeline_Order_Date: #N/A
Name Slicer_Category: #N/A
Name Slicer_Order_Status: #N/A
Name Slicer_Payment_Method: #N/A
Name Slicer_Region: #N/A

Sheet questions
G4: Q1. How are total sales and profit changing month by month? Use: Line Chart — Monthly Sales, Monthly Profit, Growth %
G5: Q2. Which product categories generate the highest revenue? Use: Column Chart — Category, Sales, Profi
G6: Q3. Which products are the best and worst performers? Create: Top 10 Products, Bottom 10 Products — Sales, Quantity, Profit
G7: Q4. Which regions and states generate the most sales? Use: Region comparison, State-level analysis, Map chart if available
G8: Q5. Which customers contribute the most revenue? Create: Top 10 Customers — Customer Sales, Orders, Average Order Value
G9: Q6. Does discounting increase sales but reduce profitability? Analyze: Discount %, Sales, Profit Margin, Quantity
G10: Q7. Which payment methods and marketing channels perform best? Compare: Payment Mode, Marketing Channel — Orders, Sales, Conversion/Revenue contribution

Sheet Raw Data
A1: Order ID | B1: Order Date | C1: Customer ID | D1: Customer Type | E1: Product ID | F1: Product Name | G1: Category | H1: Brand | I1: City | J1: Sales Channel | K1: Units | L1: Unit Price | M1: Discount % | N1: Sales Amount | O1: Profit | P1: Order Status | Q1: Payment Method | R1: Shipping Type | S1: Customer Rating | T1: year | U1: month | V1: profit margin % | W1: Region | X1: State
A2: ORD0000001 | B2: 45891 | C2: CUST00914 | D2: Returning | E2: EC011 | F2: Office Chair | G2: Home | H2: IKEA | I2: Bengaluru | J2: Mobile App | K2: 1 | L2: 190 | M2: 0 | N2: 190 | O2: 65 | P2: Delivered | Q2: Credit Card | R2: Express | S2: 2.9 | T2: =YEAR(tblOrders[[#This Row],[Order Date]]) -> 2025 | U2: =TEXT(tblOrders[[#This Row],[Order Date]],"mmm-yyyy") -> Aug-2025 | V2: =tblOrders[[#This Row],[Profit]]/tblOrders[[#This Row],[Sales Amount]] -> 0.34210526 | W2: =VLOOKUP(tblOrders[[#This Row],[City]],CityRegion,2,0) -> South | X2: =VLOOKUP(tblOrders[[#This Row],[City]],lookups!A:C,3,0) -> Karnataka
A3: ORD0000002 | B3: 45766 | C3: CUST00415 | D3: Returning | E3: EC011 | F3: Office Chair | G3: Home | H3: IKEA | I3: Delhi | J3: Website | K3: 4 | L3: 190 | M3: 0 | N3: 760 | O3: 260 | P3: Delivered | Q3: Net Banking | R3: Standard | S3: 4.6 | T3: =YEAR(tblOrders[[#This Row],[Order Date]]) -> 2025 | U3: =TEXT(tblOrders[[#This Row],[Order Date]],"mmm-yyyy") -> Apr-2025 | V3: =tblOrders[[#This Row],[Profit]]/tblOrders[[#This Row],[Sales Amount]] -> 0.34210526 | W3: =VLOOKUP(tblOrders[[#This Row],[City]],CityRegion,2,0) -> North | X3: =VLOOKUP(tblOrders[[#This Row],[City]],lookups!A:C,3,0) -> Delhi
A4: ORD0000003 | B4: 45781 | C4: CUST00394 | D4: New | E4: EC008 | F4: Face Cream | G4: Beauty | H4: Nivea | I4: Kozhikode | J4: Marketplace | K4: 3 | L4: 18 | M4: 0.1 | N4: 48.6 | O4: 21.6 | P4: Delivered | Q4: Debit Card | R4: Express | S4: 2.5 | T4: =YEAR(tblOrders[[#This Row],[Order Date]]) -> 2025 | U4: =TEXT(tblOrders[[#This Row],[Order Date]],"mmm-yyyy") -> May-2025 | V4: =tblOrders[[#This Row],[Profit]]/tblOrders[[#This Row],[Sales Amount]] -> 0.44444444 | W4: =VLOOKUP(tblOrders[[#This Row],[City]],CityRegion,2,0) -> South | X4: =VLOOKUP(tblOrders[[#This Row],[City]],lookups!A:C,3,0) -> Kerala
A5: ORD0000004 | B5: 45791 | C5: CUST00414 | D5: Returning | E5: EC006 | F5: Coffee Maker | G5: Home | H5: Philips | I5: Thiruvananthapuram | J5: Website | K5: 3 | L5: 85 | M5: 0.2 | N5: 204 | O5: 48 | P5: Delivered | Q5: Debit Card | R5: Standard | S5: 4.7 | T5: =YEAR(tblOrders[[#This Row],[Order Date]]) -> 2025 | U5: =TEXT(tblOrders[[#This Row],[Order Date]],"mmm-yyyy") -> May-2025 | V5: =tblOrders[[#This Row],[Profit]]/tblOrders[[#This Row],[Sales Amount]] -> 0.23529412 | W5: =VLOOKUP(tblOrders[[#This Row],[City]],CityRegion,2,0) -> South | X5: =VLOOKUP(tblOrders[[#This Row],[City]],lookups!A:C,3,0) -> Kerala
A6: ORD0000005 | B6: 45879 | C6: CUST00517 | D6: Returning | E6: EC012 | F6: Desk Lamp | G6: Home | H6: Philips | I6: Thrissur | J6: Marketplace | K6: 4 | L6: 42 | M6: 0.1 | N6: 151.2 | O6: 55.2 | P6: Delivered | Q6: Debit Card | R6: Express | S6: 3.3 | T6: =YEAR(tblOrders[[#This Row],[Order Date]]) -> 2025 | U6: =TEXT(tblOrders[[#This Row],[Order Date]],"mmm-yyyy") -> Aug-2025 | V6: =tblOrders[[#This Row],[Profit]]/tblOrders[[#This Row],[Sales Amount]] -> 0.36507937 | W6: =VLOOKUP(tblOrders[[#This Row],[City]],CityRegion,2,0) -> South | X6: =VLOOKUP(tblOrders[[#This Row],[City]],lookups!A:C,3,0) -> Kerala
A7: ORD0000006 | B7: 45772 | C7: CUST00196 | D7: Returning | E7: EC005 | F7: Backpack | G7: Fashion | H7: Skybags | I7: Kozhikode | J7: Mobile App | K7: 4 | L7: 45 | M7: 0.1 | N7: 162 | O7: 58 | P7: Delivered | Q7: Credit Card | R7: Standard | S7: 3 | T7: =YEAR(tblOrders[[#This Row],[Order Date]]) -> 2025 | U7: =TEXT(tblOrders[[#This Row],[Order Date]],"mmm-yyyy") -> Apr-2025 | V7: =tblOrders[[#This Row],[Profit]]/tblOrders[[#This Row],[Sales Amount]] -> 0.35802469 | W7: =VLOOKUP(tblOrders[[#This Row],[City]],CityRegion,2,0) -> South | X7: =VLOOKUP(tblOrders[[#This Row],[City]],lookups!A:C,3,0) -> Kerala
A8: ORD0000007 | B8: 45858 | C8: CUST01127 | D8: Returning | E8: EC002 | F8: Smart Watch | G8: Electronics | H8: Samsung | I8: Hyderabad | J8: Mobile App | K8: 4 | L8: 149 | M8: 0.2 | N8: 476.8 | O8: 96.8 | P8: Delivered | Q8: Debit Card | R8: Standard | S8: 4.2 | T8: =YEAR(tblOrders[[#This Row],[Order Date]]) -> 2025 | U8: =TEXT(tblOrders[[#This Row],[Order Date]],"mmm-yyyy") -> Jul-2025 | V8: =tblOrders[[#This Row],[Profit]]/tblOrders[[#This Row],[Sales Amount]] -> 0.20302013 | W8: =VLOOKUP(tblOrders[[#This Row],[City]],CityRegion,2,0) -> South | X8: =VLOOKUP(tblOrders[[#This Row],[City]],lookups!A:C,3,0) -> Telengana
A9: ORD0000008 | B9: 45809 | C9: CUST01993 | D9: Returning | E9: EC010 | F9: Bluetooth Speaker | G9: Electronics | H9: JBL | I9: Kochi | J9: Marketplace | K9: 3 | L9: 65 | M9: 0.2 | N9: 156 | O9: 42 | P9: Delivered | Q9: Debit Card | R9: Standard | S9: 2.7 | T9: =YEAR(tblOrders[[#This Row],[Order Date]]) -> 2025 | U9: =TEXT(tblOrders[[#This Row],[Order Date]],"mmm-yyyy") -> Jun-2025 | V9: =tblOrders[[#This Row],[Profit]]/tblOrders[[#This Row],[Sales Amount]] -> 0.26923077 | W9: =VLOOKUP(tblOrders[[#This Row],[City]],CityRegion,2,0) -> South | X9: =VLOOKUP(tblOrders[[#This Row],[City]],lookups!A:C,3,0) -> Kerala
A10: ORD0000009 | B10: 46019 | C10: CUST00883 | D10: Returning | E10: EC003 | F10: Laptop | G10: Electronics | H10: Lenovo | I10: Kochi | J10: Marketplace | K10: 5 | L10: 799 | M10: 0.1 | N10: 3595.5 | O10: 495.5 | P10: Delivered | Q10: Net Banking | R10: Standard | S10: 3.5 | T10: =YEAR(tblOrders[[#This Row],[Order Date]]) -> 2025 | U10: =TEXT(tblOrders[[#This Row],[Order Date]],"mmm-yyyy") -> Dec-2025 | V10: =tblOrders[[#This Row],[Profit]]/tblOrders[[#This Row],[Sales Amount]] -> 0.13781115 | W10: =VLOOKUP(tblOrders[[#This Row],[City]],CityRegion,2,0) -> South | X10: =VLOOKUP(tblOrders[[#This Row],[City]],lookups!A:C,3,0) -> Kerala
A11: ORD0000010 | B11: 46007 | C11: CUST02366 | D11: Returning | E11: EC003 | F11: Laptop | G11: Electronics | H11: Lenovo | I11: Pune | J11: Website | K11: 4 | L11: 799 | M11: 0.1 | N11: 2876.4 | O11: 396.4 | P11: Returned | Q11: UPI | R11: Standard | S11: 3.2 | T11: =YEAR(tblOrders[[#This Row],[Order Date]]) -> 2025 | U11: =TEXT(tblOrders[[#This Row],[Order Date]],"mmm-yyyy") -> Dec-2025 | V11: =tblOrders[[#This Row],[Profit]]/tblOrders[[#This Row],[Sales Amount]] -> 0.13781115 | W11: =VLOOKUP(tblOrders[[#This Row],[City]],CityRegion,2,0) -> West | X11: =VLOOKUP(tblOrders[[#This Row],[City]],lookups!A:C,3,0) -> Maharashtra
A12: ORD0000011 | B12: 45903 | C12: CUST00150 | D12: New | E12: EC012 | F12: Desk Lamp | G12: Home | H12: Philips | I12: Bengaluru | J12: Mobile App | K12: 2 | L12: 42 | M12: 0 | N12: 84 | O12: 36 | P12: Delivered | Q12: UPI | R12: Standard | S12: 4 | T12: =YEAR(tblOrders[[#This Row],[Order Date]]) -> 2025 | U12: =TEXT(tblOrders[[#This Row],[Order Date]],"mmm-yyyy") -> Sep-2025 | V12: =tblOrders[[#This Row],[Profit]]/tblOrders[[#This Row],[Sales Amount]] -> 0.42857143 | W12: =VLOOKUP(tblOrders[[#This Row],[City]],CityRegion,2,0) -> South | X12: =VLOOKUP(tblOrders[[#This Row],[City]],lookups!A:C,3,0) -> Karnataka
A13: ORD0000012 | B13: 45983 | C13: CUST00759 | D13: New | E13: EC006 | F13: Coffee Maker | G13: Home | H13: Philips | I13: Delhi | J13: Website | K13: 3 | L13: 85 | M13: 0.1 | N13: 229.5 | O13: 73.5 | P13: Delivered | Q13: COD | R13: Standard | S13: 4.1 | T13: =YEAR(tblOrders[[#This Row],[Order Date]]) -> 2025 | U13: =TEXT(tblOrders[[#This Row],[Order Date]],"mmm-yyyy") -> Nov-2025 | V13: =tblOrders[[#This Row],[Profit]]/tblOrders[[#This Row],[Sales Amount]] -> 0.32026144 | W13: =VLOOKUP(tblOrders[[#This Row],[City]],CityRegion,2,0) -> North | X13: =VLOOKUP(tblOrders[[#This Row],[City]],lookups!A:C,3,0) -> Delhi
... A7001: ORD0007000 | B7001: 45889 | C7001: CUST00083 | D7001: Returning | E7001: EC011 | F7001: Office Chair | G7001: Home | H7001: IKEA | I7001: Mumbai | J7001: Marketplace | K7001: 4 | L7001: 190 | M7001: 0.05 | N7001: 722 | O7001: 222 | P7001: Delivered | Q7001: Debit Card | R7001: Standard | S7001: 4.3 | T7001: =YEAR(tblOrders[[#This Row],[Order Date]]) -> 2025 | U7001: =TEXT(tblOrders[[#This Row],[Order Date]],"mmm-yyyy") -> Aug-2025 | V7001: =tblOrders[[#This Row],[Profit]]/tblOrders[[#This Row],[Sales Amount]] -> 0.30747922 | W7001: =VLOOKUP(tblOrders[[#This Row],[City]],CityRegion,2,0) -> West | X7001: =VLOOKUP(tblOrders[[#This Row],[City]],lookups!A:C,3,0) -> Maharashtra

Sheet lookups
A1: City | B1: Region | C1: State
A2: Delhi | B2: North | C2: Delhi
A3: Mumbai | B3: West | C3: Maharashtra
A4: Pune | B4: West | C4: Maharashtra
A5: Bengaluru | B5: South | C5: Karnataka
A6: Chennai | B6: South | C6: Tamil Nadu
A7: Hyderabad | B7: South | C7: Telengana
A8: Kochi | B8: South | C8: Kerala
A9: Kozhikode | B9: South | C9: Kerala
A10: Thiruvananthapuram | B10: South | C10: Kerala
A11: Thrissur | B11: South | C11: Kerala

Sheet PivotData
A1: Row Labels | B1: Sum of Sales Amount | C1: Sum of Profit | D1: Sales Growth | G1: TOTAL SALES | H1: =GETPIVOTDATA("Sum of Sales Amount",$A$1) -> 2728060.8 | K1: Count of Order ID | M1: Distinct Count of Customer ID | P1: Row Labels | Q1: Count of Order ID
A2: Jan | B2: 238964.2 | C2: 50585.2 | K2: 7000 | M2: 2359 | P2: Cancelled | Q2: 297
A3: Feb | B3: 193336.75 | C3: 45989.75 | D3: -0.19093843 | G3: TOTAL PROFIT | H3: =GETPIVOTDATA("Sum of Profit",$A$1) -> 615503.75 | P3: Delivered | Q3: 5604
A4: Mar | B4: 226949.55 | C4: 54137.55 | D4: 0.17385624 | K4: PROFIT MARGIN | L4: =H1/H3 -> 4.4322407 | P4: Returned | Q4: 398
A5: Apr | B5: 236778.2 | C5: 52800.2 | D5: 0.043307643 | G5: TOTAL ORDERS | H5: =GETPIVOTDATA("Order ID",$K$1) -> 7000 | P5: Shipped | Q5: 701
A6: May | B6: 224974.45 | C6: 49557.45 | D6: -0.049851507 | P6: Grand Total | Q6: 7000
A7: Jun | B7: 213493.45 | C7: 48868.45 | D7: -0.051032462 | K7: Sum of Units
A8: Jul | B8: 240590.8 | C8: 52508.8 | D8: 0.12692357 | G8: TOTAL CUSTOMERS | H8: =GETPIVOTDATA("[Measures].[Distinct Count of Customer ID]",$M$1) -> 2359 | K8: 20935
A9: Aug | B9: 240496.65 | C9: 56227.65 | D9: -0.00039132835
A10: Sep | B10: 229300.75 | C10: 52911.75 | D10: -0.046553247 | G10: PROFIT MARGIN | H10: =GETPIVOTDATA("Sum of Profit",PivotData!$A$1)/GETPIVOTDATA("Sum of Sales Amount",PivotData!$A$1) -> 0.22561952
A11: Oct | B11: 231320.65 | C11: 51712.65 | D11: 0.0088089551
A12: Nov | B12: 199286.3 | C12: 45440.3 | D12: -0.13848461
A13: Dec | B13: 252569 | C13: 54764 | D13: 0.2673676 | G13: AVERAGE ORDER VALUE | H13: =GETPIVOTDATA("Sum of Sales Amount",$A$1)/GETPIVOTDATA("Order ID",$K$1) -> 389.72296
A14: Grand Total | B14: 2728060.8 | C14: 615503.75
G17: RETURN RATE | H17: =GETPIVOTDATA("Order ID",$P$1,"Order Status","Returned")/GETPIVOTDATA("Order ID",$P$1) -> 0.056857143
A18: sales by category
A19: Row Labels | B19: Sum of Sales Amount | C19: Sum of Profit
A20: Electronics | B20: 1766805.9 | C20: 320189.85 | G20: TOTAL QUANTITY SOLD | H20: =GETPIVOTDATA("Units",$K$7) -> 20935
A21: Home | B21: 670230.7 | C21: 194497.7
A22: Fashion | B22: 244137.5 | C22: 79999.5
A23: Beauty | B23: 46886.7 | C23: 20816.7
A24: Grand Total | B24: 2728060.8 | C24: 615503.75
A29: top 10 products | F29: bottom 10 products
A30: Row Labels | B30: Sum of Sales Amount | C30: Sum of Profit | D30: Sum of Units | F30: Row Labels | G30: Sum of Sales Amount | H30: Sum of Profit | I30: Sum of Units
A31: Desk Lamp | B31: 63781.2 | C31: 23581.2 | D31: 1675 | F31: Smart Watch | G31: 223120.05 | H31: 64375.05 | I31: 1671
A32: Backpack | B32: 67131 | C32: 24101 | D32: 1655 | F32: Air Fryer | G32: 186774 | H32: 52770 | I32: 1718
A33: Bluetooth Speaker | B33: 103684.75 | C33: 36158.75 | D33: 1777 | F33: Running Shoes | G33: 177006.5 | H33: 55898.5 | I33: 1781 | L33: Row Labels | M33: Sum of Sales Amount | N33: Count of Order ID | O33: Sum of Profit
A34: Coffee Maker | B34: 135872.5 | C34: 43468.5 | D34: 1777 | F34: Wireless Headphones | G34: 154210.3 | H34: 48005.3 | I34: 1931 | L34: New | M34: 929150 | N34: 2420 | O34: 208380
A35: Wireless Headphones | B35: 154210.3 | C35: 48005.3 | D35: 1931 | F35: Coffee Maker | G35: 135872.5 | H35: 43468.5 | I35: 1777 | L35: Returning | M35: 1798910.8 | N35: 4580 | O35: 407123.75
A36: Running Shoes | B36: 177006.5 | C36: 55898.5 | D36: 1781 | F36: Bluetooth Speaker | G36: 103684.75 | H36: 36158.75 | I36: 1777 | L36: Grand Total | M36: 2728060.7 | N36: 7000 | O36: 615503.75
A37: Air Fryer | B37: 186774 | C37: 52770 | D37: 1718 | F37: Backpack | G37: 67131 | H37: 24101 | I37: 1655
A38: Smart Watch | B38: 223120.05 | C38: 64375.05 | D38: 1671 | F38: Desk Lamp | G38: 63781.2 | H38: 23581.2 | I38: 1675
A39: Office Chair | B39: 283803 | C39: 74678 | D39: 1673 | F39: Face Cream | G39: 28014.3 | H39: 12444.3 | I39: 1730
A40: Laptop | B40: 1285790.8 | C40: 171650.75 | D40: 1797 | F40: Shampoo | G40: 18872.4 | H40: 8372.4 | I40: 1750
A41: Grand Total | B41: 2681174.1 | C41: 594687.05 | D41: 17455 | F41: Grand Total | G41: 1158467 | H41: 369175 | I41: 17465
A45: SALES BY REGION
A46: Row Labels | B46: Sum of Sales Amount
A47: South | B47: 1867490.1
A48: Hyderabad | B48: 279963.55
A49: Thrissur | B49: 272537.05
...

Sheet overview

Sheet Trend&Category

Sheet Products

Sheet customers

Sheet discount&channels
